2018-11-01 17:36:19,402 ERROR: Exception on /plot [GET] [in c:\users\erroden\appdata\local\continuum\anaconda3\envs\mlg_2\lib\site-packages\flask\app.py:1761]
Traceback (most recent call last):
  File "c:\users\erroden\appdata\local\continuum\anaconda3\envs\mlg_2\lib\site-packages\flask\app.py", line 2292, in wsgi_app
    response = self.full_dispatch_request()
  File "c:\users\erroden\appdata\local\continuum\anaconda3\envs\mlg_2\lib\site-packages\flask\app.py", line 1815, in full_dispatch_request
    rv = self.handle_user_exception(e)
  File "c:\users\erroden\appdata\local\continuum\anaconda3\envs\mlg_2\lib\site-packages\flask\app.py", line 1718, in handle_user_exception
    reraise(exc_type, exc_value, tb)
  File "c:\users\erroden\appdata\local\continuum\anaconda3\envs\mlg_2\lib\site-packages\flask\_compat.py", line 35, in reraise
    raise value
  File "c:\users\erroden\appdata\local\continuum\anaconda3\envs\mlg_2\lib\site-packages\flask\app.py", line 1813, in full_dispatch_request
    rv = self.dispatch_request()
  File "c:\users\erroden\appdata\local\continuum\anaconda3\envs\mlg_2\lib\site-packages\flask\app.py", line 1799, in dispatch_request
    return self.view_functions[rule.endpoint](**req.view_args)
  File "C:\Users\erroden\Desktop\Capstone\microblog\app\routes.py", line 201, in plot
    p = text_plot
NameError: name 'text_plot' is not defined
2018-11-01 17:36:19,640 ERROR: Exception on /plot2 [GET] [in c:\users\erroden\appdata\local\continuum\anaconda3\envs\mlg_2\lib\site-packages\flask\app.py:1761]
Traceback (most recent call last):
  File "c:\users\erroden\appdata\local\continuum\anaconda3\envs\mlg_2\lib\site-packages\flask\app.py", line 2292, in wsgi_app
    response = self.full_dispatch_request()
  File "c:\users\erroden\appdata\local\continuum\anaconda3\envs\mlg_2\lib\site-packages\flask\app.py", line 1815, in full_dispatch_request
    rv = self.handle_user_exception(e)
  File "c:\users\erroden\appdata\local\continuum\anaconda3\envs\mlg_2\lib\site-packages\flask\app.py", line 1718, in handle_user_exception
    reraise(exc_type, exc_value, tb)
  File "c:\users\erroden\appdata\local\continuum\anaconda3\envs\mlg_2\lib\site-packages\flask\_compat.py", line 35, in reraise
    raise value
  File "c:\users\erroden\appdata\local\continuum\anaconda3\envs\mlg_2\lib\site-packages\flask\app.py", line 1813, in full_dispatch_request
    rv = self.dispatch_request()
  File "c:\users\erroden\appdata\local\continuum\anaconda3\envs\mlg_2\lib\site-packages\flask\app.py", line 1799, in dispatch_request
    return self.view_functions[rule.endpoint](**req.view_args)
  File "C:\Users\erroden\Desktop\Capstone\microblog\app\routes.py", line 207, in plot2
    p = full_plot
NameError: name 'full_plot' is not defined
2018-11-01 17:40:44,941 INFO: Microblog startup [in C:\Users\erroden\Desktop\Capstone\microblog\app\__init__.py:49]
2018-11-01 17:41:11,865 ERROR: Exception on /plot [GET] [in c:\users\erroden\appdata\local\continuum\anaconda3\envs\mlg_2\lib\site-packages\flask\app.py:1761]
Traceback (most recent call last):
  File "c:\users\erroden\appdata\local\continuum\anaconda3\envs\mlg_2\lib\site-packages\flask\app.py", line 2292, in wsgi_app
    response = self.full_dispatch_request()
  File "c:\users\erroden\appdata\local\continuum\anaconda3\envs\mlg_2\lib\site-packages\flask\app.py", line 1815, in full_dispatch_request
    rv = self.handle_user_exception(e)
  File "c:\users\erroden\appdata\local\continuum\anaconda3\envs\mlg_2\lib\site-packages\flask\app.py", line 1718, in handle_user_exception
    reraise(exc_type, exc_value, tb)
  File "c:\users\erroden\appdata\local\continuum\anaconda3\envs\mlg_2\lib\site-packages\flask\_compat.py", line 35, in reraise
    raise value
  File "c:\users\erroden\appdata\local\continuum\anaconda3\envs\mlg_2\lib\site-packages\flask\app.py", line 1813, in full_dispatch_request
    rv = self.dispatch_request()
  File "c:\users\erroden\appdata\local\continuum\anaconda3\envs\mlg_2\lib\site-packages\flask\app.py", line 1799, in dispatch_request
    return self.view_functions[rule.endpoint](**req.view_args)
  File "C:\Users\erroden\Desktop\Capstone\microblog\app\routes.py", line 201, in plot
    p = text_plot
NameError: name 'text_plot' is not defined
2018-11-01 17:41:11,946 ERROR: Exception on /plot2 [GET] [in c:\users\erroden\appdata\local\continuum\anaconda3\envs\mlg_2\lib\site-packages\flask\app.py:1761]
Traceback (most recent call last):
  File "c:\users\erroden\appdata\local\continuum\anaconda3\envs\mlg_2\lib\site-packages\flask\app.py", line 2292, in wsgi_app
    response = self.full_dispatch_request()
  File "c:\users\erroden\appdata\local\continuum\anaconda3\envs\mlg_2\lib\site-packages\flask\app.py", line 1815, in full_dispatch_request
    rv = self.handle_user_exception(e)
  File "c:\users\erroden\appdata\local\continuum\anaconda3\envs\mlg_2\lib\site-packages\flask\app.py", line 1718, in handle_user_exception
    reraise(exc_type, exc_value, tb)
  File "c:\users\erroden\appdata\local\continuum\anaconda3\envs\mlg_2\lib\site-packages\flask\_compat.py", line 35, in reraise
    raise value
  File "c:\users\erroden\appdata\local\continuum\anaconda3\envs\mlg_2\lib\site-packages\flask\app.py", line 1813, in full_dispatch_request
    rv = self.dispatch_request()
  File "c:\users\erroden\appdata\local\continuum\anaconda3\envs\mlg_2\lib\site-packages\flask\app.py", line 1799, in dispatch_request
    return self.view_functions[rule.endpoint](**req.view_args)
  File "C:\Users\erroden\Desktop\Capstone\microblog\app\routes.py", line 207, in plot2
    p = full_plot
NameError: name 'full_plot' is not defined
2018-11-01 17:44:21,268 INFO: Microblog startup [in C:\Users\erroden\Desktop\Capstone\microblog\app\__init__.py:49]
2018-11-01 17:44:46,600 ERROR: Exception on /plot [GET] [in c:\users\erroden\appdata\local\continuum\anaconda3\envs\mlg_2\lib\site-packages\flask\app.py:1761]
Traceback (most recent call last):
  File "c:\users\erroden\appdata\local\continuum\anaconda3\envs\mlg_2\lib\site-packages\flask\app.py", line 2292, in wsgi_app
    response = self.full_dispatch_request()
  File "c:\users\erroden\appdata\local\continuum\anaconda3\envs\mlg_2\lib\site-packages\flask\app.py", line 1815, in full_dispatch_request
    rv = self.handle_user_exception(e)
  File "c:\users\erroden\appdata\local\continuum\anaconda3\envs\mlg_2\lib\site-packages\flask\app.py", line 1718, in handle_user_exception
    reraise(exc_type, exc_value, tb)
  File "c:\users\erroden\appdata\local\continuum\anaconda3\envs\mlg_2\lib\site-packages\flask\_compat.py", line 35, in reraise
    raise value
  File "c:\users\erroden\appdata\local\continuum\anaconda3\envs\mlg_2\lib\site-packages\flask\app.py", line 1813, in full_dispatch_request
    rv = self.dispatch_request()
  File "c:\users\erroden\appdata\local\continuum\anaconda3\envs\mlg_2\lib\site-packages\flask\app.py", line 1799, in dispatch_request
    return self.view_functions[rule.endpoint](**req.view_args)
  File "C:\Users\erroden\Desktop\Capstone\microblog\app\routes.py", line 202, in plot
    return json.dumps(json_item(p, "myplot"))
NameError: name 'json' is not defined
2018-11-01 17:44:46,747 ERROR: Exception on /plot2 [GET] [in c:\users\erroden\appdata\local\continuum\anaconda3\envs\mlg_2\lib\site-packages\flask\app.py:1761]
Traceback (most recent call last):
  File "c:\users\erroden\appdata\local\continuum\anaconda3\envs\mlg_2\lib\site-packages\flask\app.py", line 2292, in wsgi_app
    response = self.full_dispatch_request()
  File "c:\users\erroden\appdata\local\continuum\anaconda3\envs\mlg_2\lib\site-packages\flask\app.py", line 1815, in full_dispatch_request
    rv = self.handle_user_exception(e)
  File "c:\users\erroden\appdata\local\continuum\anaconda3\envs\mlg_2\lib\site-packages\flask\app.py", line 1718, in handle_user_exception
    reraise(exc_type, exc_value, tb)
  File "c:\users\erroden\appdata\local\continuum\anaconda3\envs\mlg_2\lib\site-packages\flask\_compat.py", line 35, in reraise
    raise value
  File "c:\users\erroden\appdata\local\continuum\anaconda3\envs\mlg_2\lib\site-packages\flask\app.py", line 1813, in full_dispatch_request
    rv = self.dispatch_request()
  File "c:\users\erroden\appdata\local\continuum\anaconda3\envs\mlg_2\lib\site-packages\flask\app.py", line 1799, in dispatch_request
    return self.view_functions[rule.endpoint](**req.view_args)
  File "C:\Users\erroden\Desktop\Capstone\microblog\app\routes.py", line 208, in plot2
    return json.dumps(json_item(p, "myplot2"))
NameError: name 'json' is not defined
2018-11-01 17:55:41,041 INFO: Microblog startup [in C:\Users\erroden\Desktop\Capstone\microblog\app\__init__.py:49]
2018-11-01 18:04:58,114 INFO: Microblog startup [in C:\Users\erroden\Desktop\Capstone\microblog\app\__init__.py:49]
