2018-10-01 20:35:24,785 INFO: Microblog startup [in C:\Users\erroden\Desktop\Capstone\microblog\app\__init__.py:48]
2018-10-01 20:35:58,208 ERROR: Exception on /results [GET] [in c:\users\erroden\appdata\local\continuum\anaconda3\envs\mlg_2\lib\site-packages\flask\app.py:1761]
Traceback (most recent call last):
  File "c:\users\erroden\appdata\local\continuum\anaconda3\envs\mlg_2\lib\site-packages\flask\app.py", line 2292, in wsgi_app
    response = self.full_dispatch_request()
  File "c:\users\erroden\appdata\local\continuum\anaconda3\envs\mlg_2\lib\site-packages\flask\app.py", line 1815, in full_dispatch_request
    rv = self.handle_user_exception(e)
  File "c:\users\erroden\appdata\local\continuum\anaconda3\envs\mlg_2\lib\site-packages\flask\app.py", line 1718, in handle_user_exception
    reraise(exc_type, exc_value, tb)
  File "c:\users\erroden\appdata\local\continuum\anaconda3\envs\mlg_2\lib\site-packages\flask\_compat.py", line 35, in reraise
    raise value
  File "c:\users\erroden\appdata\local\continuum\anaconda3\envs\mlg_2\lib\site-packages\flask\app.py", line 1813, in full_dispatch_request
    rv = self.dispatch_request()
  File "c:\users\erroden\appdata\local\continuum\anaconda3\envs\mlg_2\lib\site-packages\flask\app.py", line 1799, in dispatch_request
    return self.view_functions[rule.endpoint](**req.view_args)
  File "C:\Users\erroden\Desktop\Capstone\microblog\app\routes.py", line 237, in results
    text_html.save()
AttributeError: 'str' object has no attribute 'save'
2018-10-01 20:39:58,040 INFO: Microblog startup [in C:\Users\erroden\Desktop\Capstone\microblog\app\__init__.py:48]
2018-10-01 20:40:19,285 ERROR: Exception on /results [GET] [in c:\users\erroden\appdata\local\continuum\anaconda3\envs\mlg_2\lib\site-packages\flask\app.py:1761]
Traceback (most recent call last):
  File "c:\users\erroden\appdata\local\continuum\anaconda3\envs\mlg_2\lib\site-packages\flask\app.py", line 2292, in wsgi_app
    response = self.full_dispatch_request()
  File "c:\users\erroden\appdata\local\continuum\anaconda3\envs\mlg_2\lib\site-packages\flask\app.py", line 1815, in full_dispatch_request
    rv = self.handle_user_exception(e)
  File "c:\users\erroden\appdata\local\continuum\anaconda3\envs\mlg_2\lib\site-packages\flask\app.py", line 1718, in handle_user_exception
    reraise(exc_type, exc_value, tb)
  File "c:\users\erroden\appdata\local\continuum\anaconda3\envs\mlg_2\lib\site-packages\flask\_compat.py", line 35, in reraise
    raise value
  File "c:\users\erroden\appdata\local\continuum\anaconda3\envs\mlg_2\lib\site-packages\flask\app.py", line 1813, in full_dispatch_request
    rv = self.dispatch_request()
  File "c:\users\erroden\appdata\local\continuum\anaconda3\envs\mlg_2\lib\site-packages\flask\app.py", line 1799, in dispatch_request
    return self.view_functions[rule.endpoint](**req.view_args)
  File "C:\Users\erroden\Desktop\Capstone\microblog\app\routes.py", line 238, in results
    f.write(html)
NameError: name 'html' is not defined
2018-10-01 20:40:52,502 INFO: Microblog startup [in C:\Users\erroden\Desktop\Capstone\microblog\app\__init__.py:48]
