2018-10-02 10:59:19,050 INFO: Microblog startup [in C:\Users\erroden\Desktop\Capstone\microblog\app\__init__.py:48]
2018-10-11 23:00:07,678 INFO: Microblog startup [in C:\Users\erroden\Desktop\Capstone\microblog\app\__init__.py:48]
2018-10-12 00:17:02,680 INFO: Microblog startup [in C:\Users\erroden\Desktop\Capstone\microblog\app\__init__.py:48]
2018-10-12 00:17:55,292 INFO: Microblog startup [in C:\Users\erroden\Desktop\Capstone\microblog\app\__init__.py:48]
2018-10-14 22:35:21,301 INFO: Microblog startup [in C:\Users\erroden\Desktop\Capstone\microblog\app\__init__.py:48]
2018-10-15 06:23:34,580 INFO: Microblog startup [in C:\Users\erroden\Desktop\Capstone\microblog\app\__init__.py:48]
2018-10-15 08:44:09,992 INFO: Microblog startup [in C:\Users\erroden\Desktop\Capstone\microblog\app\__init__.py:48]
2018-10-17 09:51:09,148 INFO: Microblog startup [in C:\Users\erroden\Desktop\Capstone\microblog\app\__init__.py:48]
2018-10-17 09:52:41,813 INFO: Microblog startup [in C:\Users\erroden\Desktop\Capstone\microblog\app\__init__.py:48]
2018-10-17 09:57:10,335 INFO: Microblog startup [in C:\Users\erroden\Desktop\Capstone\microblog\app\__init__.py:48]
2018-10-24 16:19:39,520 INFO: Microblog startup [in C:\Users\erroden\Desktop\Capstone\microblog\app\__init__.py:48]
2018-10-24 17:09:50,144 INFO: Microblog startup [in C:\Users\erroden\Desktop\Capstone\microblog\app\__init__.py:48]
2018-10-24 17:10:31,677 ERROR: Exception on /results [GET] [in c:\users\erroden\appdata\local\continuum\anaconda3\envs\mlg_2\lib\site-packages\flask\app.py:1761]
Traceback (most recent call last):
  File "c:\users\erroden\appdata\local\continuum\anaconda3\envs\mlg_2\lib\site-packages\flask\app.py", line 2292, in wsgi_app
    response = self.full_dispatch_request()
  File "c:\users\erroden\appdata\local\continuum\anaconda3\envs\mlg_2\lib\site-packages\flask\app.py", line 1815, in full_dispatch_request
    rv = self.handle_user_exception(e)
  File "c:\users\erroden\appdata\local\continuum\anaconda3\envs\mlg_2\lib\site-packages\flask\app.py", line 1718, in handle_user_exception
    reraise(exc_type, exc_value, tb)
  File "c:\users\erroden\appdata\local\continuum\anaconda3\envs\mlg_2\lib\site-packages\flask\_compat.py", line 35, in reraise
    raise value
  File "c:\users\erroden\appdata\local\continuum\anaconda3\envs\mlg_2\lib\site-packages\flask\app.py", line 1813, in full_dispatch_request
    rv = self.dispatch_request()
  File "c:\users\erroden\appdata\local\continuum\anaconda3\envs\mlg_2\lib\site-packages\flask\app.py", line 1799, in dispatch_request
    return self.view_functions[rule.endpoint](**req.view_args)
  File "C:\Users\erroden\Desktop\Capstone\microblog\app\routes.py", line 228, in results
    text_data = {"Recommend": ['No', 'Yes'], "Probability": [text_prob[0], text_prob[1]], 'color': list(palettes.brewer['Pastel1'][2])}
KeyError: 2
2018-10-24 17:15:55,561 INFO: Microblog startup [in C:\Users\erroden\Desktop\Capstone\microblog\app\__init__.py:48]
