2018-09-18 21:13:03,985 ERROR: Exception on /register [GET] [in c:\users\erroden\appdata\local\continuum\anaconda3\envs\mlg_2\lib\site-packages\flask\app.py:1761]
Traceback (most recent call last):
  File "c:\users\erroden\appdata\local\continuum\anaconda3\envs\mlg_2\lib\site-packages\flask\app.py", line 2292, in wsgi_app
    response = self.full_dispatch_request()
  File "c:\users\erroden\appdata\local\continuum\anaconda3\envs\mlg_2\lib\site-packages\flask\app.py", line 1815, in full_dispatch_request
    rv = self.handle_user_exception(e)
  File "c:\users\erroden\appdata\local\continuum\anaconda3\envs\mlg_2\lib\site-packages\flask\app.py", line 1718, in handle_user_exception
    reraise(exc_type, exc_value, tb)
  File "c:\users\erroden\appdata\local\continuum\anaconda3\envs\mlg_2\lib\site-packages\flask\_compat.py", line 35, in reraise
    raise value
  File "c:\users\erroden\appdata\local\continuum\anaconda3\envs\mlg_2\lib\site-packages\flask\app.py", line 1813, in full_dispatch_request
    rv = self.dispatch_request()
  File "c:\users\erroden\appdata\local\continuum\anaconda3\envs\mlg_2\lib\site-packages\flask\app.py", line 1799, in dispatch_request
    return self.view_functions[rule.endpoint](**req.view_args)
  File "C:\Users\erroden\Desktop\Capstone\microblog\app\routes.py", line 87, in register
    return render_template('register.html', title='Register', form=form)
  File "c:\users\erroden\appdata\local\continuum\anaconda3\envs\mlg_2\lib\site-packages\flask\templating.py", line 135, in render_template
    context, ctx.app)
  File "c:\users\erroden\appdata\local\continuum\anaconda3\envs\mlg_2\lib\site-packages\flask\templating.py", line 117, in _render
    rv = template.render(context)
  File "c:\users\erroden\appdata\local\continuum\anaconda3\envs\mlg_2\lib\site-packages\jinja2\environment.py", line 1008, in render
    return self.environment.handle_exception(exc_info, True)
  File "c:\users\erroden\appdata\local\continuum\anaconda3\envs\mlg_2\lib\site-packages\jinja2\environment.py", line 780, in handle_exception
    reraise(exc_type, exc_value, tb)
  File "c:\users\erroden\appdata\local\continuum\anaconda3\envs\mlg_2\lib\site-packages\jinja2\_compat.py", line 37, in reraise
    raise value.with_traceback(tb)
  File "C:\Users\erroden\Desktop\Capstone\microblog\app\templates\base.html", line 32, in template
    {% block app_content %}{% endblock %}
  File "c:\users\erroden\appdata\local\continuum\anaconda3\envs\mlg_2\lib\site-packages\jinja2\environment.py", line 1005, in render
    return concat(self.root_render_func(self.new_context(vars)))
  File "C:\Users\erroden\Desktop\Capstone\microblog\app\templates\register.html", line 1, in top-level template code
    {% extends "base.html" %}
  File "c:\users\erroden\appdata\local\continuum\anaconda3\envs\mlg_2\lib\site-packages\jinja2\environment.py", line 780, in handle_exception
    reraise(exc_type, exc_value, tb)
  File "c:\users\erroden\appdata\local\continuum\anaconda3\envs\mlg_2\lib\site-packages\jinja2\_compat.py", line 37, in reraise
    raise value.with_traceback(tb)
  File "C:\Users\erroden\Desktop\Capstone\microblog\app\templates\base.html", line 32, in template
    {% block app_content %}{% endblock %}
  File "c:\users\erroden\appdata\local\continuum\anaconda3\envs\mlg_2\lib\site-packages\jinja2\environment.py", line 543, in _generate
    optimized=self.optimized)
  File "c:\users\erroden\appdata\local\continuum\anaconda3\envs\mlg_2\lib\site-packages\jinja2\compiler.py", line 82, in generate
    generator.visit(node)
  File "c:\users\erroden\appdata\local\continuum\anaconda3\envs\mlg_2\lib\site-packages\jinja2\visitor.py", line 38, in visit
    return f(node, *args, **kwargs)
  File "c:\users\erroden\appdata\local\continuum\anaconda3\envs\mlg_2\lib\site-packages\jinja2\compiler.py", line 718, in visit_Template
    self.fail('block %r defined twice' % block.name, block.lineno)
  File "c:\users\erroden\appdata\local\continuum\anaconda3\envs\mlg_2\lib\site-packages\jinja2\compiler.py", line 315, in fail
    raise TemplateAssertionError(msg, lineno, self.name, self.filename)
jinja2.exceptions.TemplateAssertionError: block 'app_content' defined twice
2018-09-18 21:13:31,010 INFO: Microblog startup [in C:\Users\erroden\Desktop\Capstone\microblog\app\__init__.py:48]
2018-09-18 21:13:39,003 ERROR: Exception on /login [GET] [in c:\users\erroden\appdata\local\continuum\anaconda3\envs\mlg_2\lib\site-packages\flask\app.py:1761]
Traceback (most recent call last):
  File "c:\users\erroden\appdata\local\continuum\anaconda3\envs\mlg_2\lib\site-packages\flask\app.py", line 2292, in wsgi_app
    response = self.full_dispatch_request()
  File "c:\users\erroden\appdata\local\continuum\anaconda3\envs\mlg_2\lib\site-packages\flask\app.py", line 1815, in full_dispatch_request
    rv = self.handle_user_exception(e)
  File "c:\users\erroden\appdata\local\continuum\anaconda3\envs\mlg_2\lib\site-packages\flask\app.py", line 1718, in handle_user_exception
    reraise(exc_type, exc_value, tb)
  File "c:\users\erroden\appdata\local\continuum\anaconda3\envs\mlg_2\lib\site-packages\flask\_compat.py", line 35, in reraise
    raise value
  File "c:\users\erroden\appdata\local\continuum\anaconda3\envs\mlg_2\lib\site-packages\flask\app.py", line 1813, in full_dispatch_request
    rv = self.dispatch_request()
  File "c:\users\erroden\appdata\local\continuum\anaconda3\envs\mlg_2\lib\site-packages\flask\app.py", line 1799, in dispatch_request
    return self.view_functions[rule.endpoint](**req.view_args)
  File "C:\Users\erroden\Desktop\Capstone\microblog\app\routes.py", line 54, in login
    return render_template('login.html', title='Sign In', form=form)
  File "c:\users\erroden\appdata\local\continuum\anaconda3\envs\mlg_2\lib\site-packages\flask\templating.py", line 135, in render_template
    context, ctx.app)
  File "c:\users\erroden\appdata\local\continuum\anaconda3\envs\mlg_2\lib\site-packages\flask\templating.py", line 117, in _render
    rv = template.render(context)
  File "c:\users\erroden\appdata\local\continuum\anaconda3\envs\mlg_2\lib\site-packages\jinja2\environment.py", line 1008, in render
    return self.environment.handle_exception(exc_info, True)
  File "c:\users\erroden\appdata\local\continuum\anaconda3\envs\mlg_2\lib\site-packages\jinja2\environment.py", line 780, in handle_exception
    reraise(exc_type, exc_value, tb)
  File "c:\users\erroden\appdata\local\continuum\anaconda3\envs\mlg_2\lib\site-packages\jinja2\_compat.py", line 37, in reraise
    raise value.with_traceback(tb)
  File "C:\Users\erroden\Desktop\Capstone\microblog\app\templates\base.html", line 32, in template
    {% block app_content %}{% endblock %}
  File "c:\users\erroden\appdata\local\continuum\anaconda3\envs\mlg_2\lib\site-packages\jinja2\environment.py", line 1005, in render
    return concat(self.root_render_func(self.new_context(vars)))
  File "C:\Users\erroden\Desktop\Capstone\microblog\app\templates\login.html", line 1, in top-level template code
    {% extends "base.html" %}
  File "c:\users\erroden\appdata\local\continuum\anaconda3\envs\mlg_2\lib\site-packages\jinja2\environment.py", line 780, in handle_exception
    reraise(exc_type, exc_value, tb)
  File "c:\users\erroden\appdata\local\continuum\anaconda3\envs\mlg_2\lib\site-packages\jinja2\_compat.py", line 37, in reraise
    raise value.with_traceback(tb)
  File "C:\Users\erroden\Desktop\Capstone\microblog\app\templates\base.html", line 32, in template
    {% block app_content %}{% endblock %}
  File "c:\users\erroden\appdata\local\continuum\anaconda3\envs\mlg_2\lib\site-packages\jinja2\environment.py", line 543, in _generate
    optimized=self.optimized)
  File "c:\users\erroden\appdata\local\continuum\anaconda3\envs\mlg_2\lib\site-packages\jinja2\compiler.py", line 82, in generate
    generator.visit(node)
  File "c:\users\erroden\appdata\local\continuum\anaconda3\envs\mlg_2\lib\site-packages\jinja2\visitor.py", line 38, in visit
    return f(node, *args, **kwargs)
  File "c:\users\erroden\appdata\local\continuum\anaconda3\envs\mlg_2\lib\site-packages\jinja2\compiler.py", line 718, in visit_Template
    self.fail('block %r defined twice' % block.name, block.lineno)
  File "c:\users\erroden\appdata\local\continuum\anaconda3\envs\mlg_2\lib\site-packages\jinja2\compiler.py", line 315, in fail
    raise TemplateAssertionError(msg, lineno, self.name, self.filename)
jinja2.exceptions.TemplateAssertionError: block 'app_content' defined twice
